Workbook

Sheet 00000

Sheet KD
A1: ELEMEN
A3: No | B3: Elemen
A4: 1 | B4: Memahami konsep dasar basis data
A5: 2 | B5: Mendeskripsikan Model Data dan Hubungan Antar Entitas
A6: 3 | B6: Mengimplementasikan Relasi Data
A7: 4
A8: 5
A9: 6
A10: 7
A11: 8
A12: 9
A13: 10
A14: 11
A15: 12
A16: 13
A17: 14
A19: =A1 -> ELEMEN
A21: No | B21: =B3 -> Elemen
A22: 1 | B22: =B4 -> Memahami konsep dasar basis data
A23: 2 | B23: =B5 -> Mendeskripsikan Model Data dan Hubungan Antar Entitas
A24: 3 | B24: =B6 -> Mengimplementasikan Relasi Data
A25: 4 | B25: =B7
A26: 5 | B26: =B8
A27: 6 | B27: =B9
A28: 7 | B28: =B10
A29: 8 | B29: =B11
A30: 9 | B30: =B12
A31: 10 | B31: =B13
A32: 11 | B32: =B14
A33: 12 | B33: =B15
... A35: 14 | B35: =B17

Sheet Pengetahuan (rincian)
A1: XIE RPL | AV1: Confidential
C2: ="DAFTAR RINCI NILAI PESERTA DIDIK KELAS "&A1 -> DAFTAR RINCI NILAI PESERTA DIDIK KELAS XIE RPL
C3: SMK TELKOM BANJARBARU
C4: TAHUN PELAJARAN 2025-2026
A6: MATA PELAJARAN : | D6: BASIS DATA | AV6: SEMESTER : GANJIL
A9: NO | B9: NOMOR INDUK | D9: NAMA SISWA | E9: NILAI PADA MASING-MASING ELEMEN | AU9: NILAI UUS
E10: =KD!B4 -> Memahami konsep dasar basis data | H10: =KD!B5 -> Mendeskripsikan Model Data dan Hubungan Antar Entitas | K10: =KD!B6 -> Mengimplementasikan Relasi Data | N10: =KD!B7 | Q10: =KD!B8 | T10: =KD!B9 | W10: =KD!B10 | Z10: =KD!B11 | AC10: =KD!B12 | AF10: =KD!B13 | AI10: =KD!B14 | AL10: =KD!B15 | AO10: =KD!B16 | AR10: =KD!B17 | AU10: NH | AV10: PTS | AX10: PAS/PAB
E11: NS | F11: R | G11: NA | H11: NS | I11: R | J11: NA | K11: NS | L11: R | M11: NA | N11: NS | O11: R | P11: NA | Q11: NS | R11: R | S11: NA | T11: NS | U11: R | V11: NA | W11: NS | X11: R | Y11: NA | Z11: NS | AA11: R | AB11: NA | AC11: NS | AD11: R | AE11: NA | AF11: NS | AG11: R | AH11: NA | AI11: NS | AJ11: R | AK11: NA | AL11: NS | AM11: R | AN11: NA | AO11: NS | AP11: R | AQ11: NA | AR11: NS | AS11: R | AT11: NA | AV11: NS | AW11: R | AX11: NS | AY11: R
A12: 1 | B12: 543241108 | D12: AHMAD FAIZH GIFFARY SYA'BANA | E12: 90 | G12: =IF(E12="","",MAX(E12:F12)) -> 90 | H12: 80 | J12: =IF(H12="","",MAX(H12:I12)) -> 80 | K12: 90 | M12: =IF(K12="","",MAX(K12:L12)) -> 90 | P12: =IF(N12="","",MAX(N12:O12)) | S12: =IF(Q12="","",MAX(Q12:R12)) | V12: =IF(T12="","",MAX(T12:U12)) | Y12: =IF(W12="","",MAX(W12:X12)) | AB12: =IF(Z12="","",MAX(Z12:AA12)) | AE12: =IF(AC12="","",MAX(AC12:AD12)) | AH12: =IF(AF12="","",MAX(AF12:AG12)) | AK12: =IF(AI12="","",MAX(AI12:AJ12)) | AN12: =IF(AL12="","",MAX(AL12:AM12)) | AQ12: =IF(AO12="","",MAX(AO12:AP12)) | AT12: =IF(AR12="","",MAX(AR12:AS12)) | AU12: =IF(E12="","",ROUND(AVERAGE(G12,J12,M12,P12,S12,V12,Y12,AB12,AE12,AH12,AK12,AN12,AQ12,AT12),0)) -> 87 | AV12: 80 | AX12: 90
A13: 2 | B13: 543241071 | D13: AHMAD SAJIDAN ATHAILLAH | E13: 90 | G13: =IF(E13="","",MAX(E13:F13)) -> 90 | H13: 80 | J13: =IF(H13="","",MAX(H13:I13)) -> 80 | K13: 90 | M13: =IF(K13="","",MAX(K13:L13)) -> 90 | P13: =IF(N13="","",MAX(N13:O13)) | S13: =IF(Q13="","",MAX(Q13:R13)) | V13: =IF(T13="","",MAX(T13:U13)) | Y13: =IF(W13="","",MAX(W13:X13)) | AB13: =IF(Z13="","",MAX(Z13:AA13)) | AE13: =IF(AC13="","",MAX(AC13:AD13)) | AH13: =IF(AF13="","",MAX(AF13:AG13)) | AK13: =IF(AI13="","",MAX(AI13:AJ13)) | AN13: =IF(AL13="","",MAX(AL13:AM13)) | AQ13: =IF(AO13="","",MAX(AO13:AP13)) | AT13: =IF(AR13="","",MAX(AR13:AS13)) | AU13: =IF(E13="","",ROUND(AVERAGE(G13,J13,M13,P13,S13,V13,Y13,AB13,AE13,AH13,AK13,AN13,AQ13,AT13),0)) -> 87 | AV13: 80 | AX13: 90
A14: 3 | B14: 543241110 | D14: AKHMAD SUPRIYADI | E14: 92 | G14: =IF(E14="","",MAX(E14:F14)) -> 92 | H14: 95 | J14: =IF(H14="","",MAX(H14:I14)) -> 95 | K14: 92 | M14: =IF(K14="","",MAX(K14:L14)) -> 92 | P14: =IF(N14="","",MAX(N14:O14)) | S14: =IF(Q14="","",MAX(Q14:R14)) | V14: =IF(T14="","",MAX(T14:U14)) | Y14: =IF(W14="","",MAX(W14:X14)) | AB14: =IF(Z14="","",MAX(Z14:AA14)) | AE14: =IF(AC14="","",MAX(AC14:AD14)) | AH14: =IF(AF14="","",MAX(AF14:AG14)) | AK14: =IF(AI14="","",MAX(AI14:AJ14)) | AN14: =IF(AL14="","",MAX(AL14:AM14)) | AQ14: =IF(AO14="","",MAX(AO14:AP14)) | AT14: =IF(AR14="","",MAX(AR14:AS14)) | AU14: =IF(E14="","",ROUND(AVERAGE(G14,J14,M14,P14,S14,V14,Y14,AB14,AE14,AH14,AK14,AN14,AQ14,AT14),0)) -> 93 | AV14: 95 | AX14: 92
A15: 4 | B15: 543241112 | D15: ALFIAH RAHMAWATI PUTRI | E15: 95 | G15: =IF(E15="","",MAX(E15:F15)) -> 95 | H15: 93 | J15: =IF(H15="","",MAX(H15:I15)) -> 93 | K15: 95 | M15: =IF(K15="","",MAX(K15:L15)) -> 95 | P15: =IF(N15="","",MAX(N15:O15)) | S15: =IF(Q15="","",MAX(Q15:R15)) | V15: =IF(T15="","",MAX(T15:U15)) | Y15: =IF(W15="","",MAX(W15:X15)) | AB15: =IF(Z15="","",MAX(Z15:AA15)) | AE15: =IF(AC15="","",MAX(AC15:AD15)) | AH15: =IF(AF15="","",MAX(AF15:AG15)) | AK15: =IF(AI15="","",MAX(AI15:AJ15)) | AN15: =IF(AL15="","",MAX(AL15:AM15)) | AQ15: =IF(AO15="","",MAX(AO15:AP15)) | AT15: =IF(AR15="","",MAX(AR15:AS15)) | AU15: =IF(E15="","",ROUND(AVERAGE(G15,J15,M15,P15,S15,V15,Y15,AB15,AE15,AH15,AK15,AN15,AQ15,AT15),0)) -> 94 | AV15: 93 | AX15: 95
A16: 5 | B16: 543241113 | D16: ARMAN DUARTE | E16: 92 | G16: =IF(E16="","",MAX(E16:F16)) -> 92 | H16: 95 | J16: =IF(H16="","",MAX(H16:I16)) -> 95 | K16: 92 | M16: =IF(K16="","",MAX(K16:L16)) -> 92 | P16: =IF(N16="","",MAX(N16:O16)) | S16: =IF(Q16="","",MAX(Q16:R16)) | V16: =IF(T16="","",MAX(T16:U16)) | Y16: =IF(W16="","",MAX(W16:X16)) | AB16: =IF(Z16="","",MAX(Z16:AA16)) | AE16: =IF(AC16="","",MAX(AC16:AD16)) | AH16: =IF(AF16="","",MAX(AF16:AG16)) | AK16: =IF(AI16="","",MAX(AI16:AJ16)) | AN16: =IF(AL16="","",MAX(AL16:AM16)) | AQ16: =IF(AO16="","",MAX(AO16:AP16)) | AT16: =IF(AR16="","",MAX(AR16:AS16)) | AU16: =IF(E16="","",ROUND(AVERAGE(G16,J16,M16,P16,S16,V16,Y16,AB16,AE16,AH16,AK16,AN16,AQ16,AT16),0)) -> 93 | AV16: 95 | AX16: 92
A17: 6 | B17: 543241114 | D17: AULIA AGUSTIANTI RAMADHANI | E17: 95 | G17: =IF(E17="","",MAX(E17:F17)) -> 95 | H17: 93 | J17: =IF(H17="","",MAX(H17:I17)) -> 93 | K17: 95 | M17: =IF(K17="","",MAX(K17:L17)) -> 95 | P17: =IF(N17="","",MAX(N17:O17)) | S17: =IF(Q17="","",MAX(Q17:R17)) | V17: =IF(T17="","",MAX(T17:U17)) | Y17: =IF(W17="","",MAX(W17:X17)) | AB17: =IF(Z17="","",MAX(Z17:AA17)) | AE17: =IF(AC17="","",MAX(AC17:AD17)) | AH17: =IF(AF17="","",MAX(AF17:AG17)) | AK17: =IF(AI17="","",MAX(AI17:AJ17)) | AN17: =IF(AL17="","",MAX(AL17:AM17)) | AQ17: =IF(AO17="","",MAX(AO17:AP17)) | AT17: =IF(AR17="","",MAX(AR17:AS17)) | AU17: =IF(E17="","",ROUND(AVERAGE(G17,J17,M17,P17,S17,V17,Y17,AB17,AE17,AH17,AK17,AN17,AQ17,AT17),0)) -> 94 | AV17: 93 | AX17: 95
A18: 7 | B18: 543241025 | D18: BETARUS MARCHIANO BOANERGES | E18: 90 | G18: =IF(E18="","",MAX(E18:F18)) -> 90 | H18: 95 | J18: =IF(H18="","",MAX(H18:I18)) -> 95 | K18: 90 | M18: =IF(K18="","",MAX(K18:L18)) -> 90 | P18: =IF(N18="","",MAX(N18:O18)) | S18: =IF(Q18="","",MAX(Q18:R18)) | V18: =IF(T18="","",MAX(T18:U18)) | Y18: =IF(W18="","",MAX(W18:X18)) | AB18: =IF(Z18="","",MAX(Z18:AA18)) | AE18: =IF(AC18="","",MAX(AC18:AD18)) | AH18: =IF(AF18="","",MAX(AF18:AG18)) | AK18: =IF(AI18="","",MAX(AI18:AJ18)) | AN18: =IF(AL18="","",MAX(AL18:AM18)) | AQ18: =IF(AO18="","",MAX(AO18:AP18)) | AT18: =IF(AR18="","",MAX(AR18:AS18)) | AU18: =IF(E18="","",ROUND(AVERAGE(G18,J18,M18,P18,S18,V18,Y18,AB18,AE18,AH18,AK18,AN18,AQ18,AT18),0)) -> 92 | AV18: 95 | AX18: 90
A19: 8 | B19: 543241078 | D19: DANIEL DIMAS NUGROHO | E19: 88 | G19: =IF(E19="","",MAX(E19:F19)) -> 88 | H19: 95 | J19: =IF(H19="","",MAX(H19:I19)) -> 95 | K19: 88 | M19: =IF(K19="","",MAX(K19:L19)) -> 88 | P19: =IF(N19="","",MAX(N19:O19)) | S19: =IF(Q19="","",MAX(Q19:R19)) | V19: =IF(T19="","",MAX(T19:U19)) | Y19: =IF(W19="","",MAX(W19:X19)) | AB19: =IF(Z19="","",MAX(Z19:AA19)) | AE19: =IF(AC19="","",MAX(AC19:AD19)) | AH19: =IF(AF19="","",MAX(AF19:AG19)) | AK19: =IF(AI19="","",MAX(AI19:AJ19)) | AN19: =IF(AL19="","",MAX(AL19:AM19)) | AQ19: =IF(AO19="","",MAX(AO19:AP19)) | AT19: =IF(AR19="","",MAX(AR19:AS19)) | AU19: =IF(E19="","",ROUND(AVERAGE(G19,J19,M19,P19,S19,V19,Y19,AB19,AE19,AH19,AK19,AN19,AQ19,AT19),0)) -> 90 | AV19: 95 | AX19: 88
A20: 9 | B20: 543241080 | D20: DEDE FEBRYLIANTONI | E20: 88 | G20: =IF(E20="","",MAX(E20:F20)) -> 88 | H20: 95 | J20: =IF(H20="","",MAX(H20:I20)) -> 95 | K20: 88 | M20: =IF(K20="","",MAX(K20:L20)) -> 88 | P20: =IF(N20="","",MAX(N20:O20)) | S20: =IF(Q20="","",MAX(Q20:R20)) | V20: =IF(T20="","",MAX(T20:U20)) | Y20: =IF(W20="","",MAX(W20:X20)) | AB20: =IF(Z20="","",MAX(Z20:AA20)) | AE20: =IF(AC20="","",MAX(AC20:AD20)) | AH20: =IF(AF20="","",MAX(AF20:AG20)) | AK20: =IF(AI20="","",MAX(AI20:AJ20)) | AN20: =IF(AL20="","",MAX(AL20:AM20)) | AQ20: =IF(AO20="","",MAX(AO20:AP20)) | AT20: =IF(AR20="","",MAX(AR20:AS20)) | AU20: =IF(E20="","",ROUND(AVERAGE(G20,J20,M20,P20,S20,V20,Y20,AB20,AE20,AH20,AK20,AN20,AQ20,AT20),0)) -> 90 | AV20: 95 | AX20: 88
A21: 10 | B21: 543241081 | D21: GHANIY PUTRI AR RAZZAQ | E21: 95 | G21: =IF(E21="","",MAX(E21:F21)) -> 95 | H21: 90 | J21: =IF(H21="","",MAX(H21:I21)) -> 90 | K21: 95 | M21: =IF(K21="","",MAX(K21:L21)) -> 95 | P21: =IF(N21="","",MAX(N21:O21)) | S21: =IF(Q21="","",MAX(Q21:R21)) | V21: =IF(T21="","",MAX(T21:U21)) | Y21: =IF(W21="","",MAX(W21:X21)) | AB21: =IF(Z21="","",MAX(Z21:AA21)) | AE21: =IF(AC21="","",MAX(AC21:AD21)) | AH21: =IF(AF21="","",MAX(AF21:AG21)) | AK21: =IF(AI21="","",MAX(AI21:AJ21)) | AN21: =IF(AL21="","",MAX(AL21:AM21)) | AQ21: =IF(AO21="","",MAX(AO21:AP21)) | AT21: =IF(AR21="","",MAX(AR21:AS21)) | AU21: =IF(E21="","",ROUND(AVERAGE(G21,J21,M21,P21,S21,V21,Y21,AB21,AE21,AH21,AK21,AN21,AQ21,AT21),0)) -> 93 | AV21: 90 | AX21: 95
A22: 11 | B22: 543241119 | D22: HAIKA MEZZIA AVEIRA | E22: 95 | G22: =IF(E22="","",MAX(E22:F22)) -> 95 | H22: 95 | J22: =IF(H22="","",MAX(H22:I22)) -> 95 | K22: 95 | M22: =IF(K22="","",MAX(K22:L22)) -> 95 | P22: =IF(N22="","",MAX(N22:O22)) | S22: =IF(Q22="","",MAX(Q22:R22)) | V22: =IF(T22="","",MAX(T22:U22)) | Y22: =IF(W22="","",MAX(W22:X22)) | AB22: =IF(Z22="","",MAX(Z22:AA22)) | AE22: =IF(AC22="","",MAX(AC22:AD22)) | AH22: =IF(AF22="","",MAX(AF22:AG22)) | AK22: =IF(AI22="","",MAX(AI22:AJ22)) | AN22: =IF(AL22="","",MAX(AL22:AM22)) | AQ22: =IF(AO22="","",MAX(AO22:AP22)) | AT22: =IF(AR22="","",MAX(AR22:AS22)) | AU22: =IF(E22="","",ROUND(AVERAGE(G22,J22,M22,P22,S22,V22,Y22,AB22,AE22,AH22,AK22,AN22,AQ22,AT22),0)) -> 95 | AV22: 95 | AX22: 95
A23: 12 | B23: 543241009 | D23: KEVIN APTA | E23: 95 | G23: =IF(E23="","",MAX(E23:F23)) -> 95 | H23: 90 | J23: =IF(H23="","",MAX(H23:I23)) -> 90 | K23: 95 | M23: =IF(K23="","",MAX(K23:L23)) -> 95 | P23: =IF(N23="","",MAX(N23:O23)) | S23: =IF(Q23="","",MAX(Q23:R23)) | V23: =IF(T23="","",MAX(T23:U23)) | Y23: =IF(W23="","",MAX(W23:X23)) | AB23: =IF(Z23="","",MAX(Z23:AA23)) | AE23: =IF(AC23="","",MAX(AC23:AD23)) | AH23: =IF(AF23="","",MAX(AF23:AG23)) | AK23: =IF(AI23="","",MAX(AI23:AJ23)) | AN23: =IF(AL23="","",MAX(AL23:AM23)) | AQ23: =IF(AO23="","",MAX(AO23:AP23)) | AT23: =IF(AR23="","",MAX(AR23:AS23)) | AU23: =IF(E23="","",ROUND(AVERAGE(G23,J23,M23,P23,S23,V23,Y23,AB23,AE23,AH23,AK23,AN23,AQ23,AT23),0)) -> 93 | AV23: 90 | AX23: 95
... A49: 38 | B49: 543241020 | D49: YEFTA CHRISTIAN LENGKONG | E49: 88 | G49: =IF(E49="","",MAX(E49:F49)) -> 88 | H49: 93 | J49: =IF(H49="","",MAX(H49:I49)) -> 93 | K49: 88 | M49: =IF(K49="","",MAX(K49:L49)) -> 88 | P49: =IF(N49="","",MAX(N49:O49)) | S49: =IF(Q49="","",MAX(Q49:R49)) | V49: =IF(T49="","",MAX(T49:U49)) | Y49: =IF(W49="","",MAX(W49:X49)) | AB49: =IF(Z49="","",MAX(Z49:AA49)) | AE49: =IF(AC49="","",MAX(AC49:AD49)) | AH49: =IF(AF49="","",MAX(AF49:AG49)) | AK49: =IF(AI49="","",MAX(AI49:AJ49)) | AN49: =IF(AL49="","",MAX(AL49:AM49)) | AQ49: =IF(AO49="","",MAX(AO49:AP49)) | AT49: =IF(AR49="","",MAX(AR49:AS49)) | AU49: =IF(E49="","",ROUND(AVERAGE(G49,J49,M49,P49,S49,V49,Y49,AB49,AE49,AH49,AK49,AN49,AQ49,AT49),0)) -> 90 | AV49: 93 | AX49: 88
A50: 39 | G50: =IF(E50="","",MAX(E50:F50)) | J50: =IF(H50="","",MAX(H50:I50)) | M50: =IF(K50="","",MAX(K50:L50)) | P50: =IF(N50="","",MAX(N50:O50)) | S50: =IF(Q50="","",MAX(Q50:R50)) | V50: =IF(T50="","",MAX(T50:U50)) | Y50: =IF(W50="","",MAX(W50:X50)) | AB50: =IF(Z50="","",MAX(Z50:AA50)) | AE50: =IF(AC50="","",MAX(AC50:AD50)) | AH50: =IF(AF50="","",MAX(AF50:AG50)) | AK50: =IF(AI50="","",MAX(AI50:AJ50)) | AN50: =IF(AL50="","",MAX(AL50:AM50)) | AQ50: =IF(AO50="","",MAX(AO50:AP50)) | AT50: =IF(AR50="","",MAX(AR50:AS50)) | AU50: =IF(E50="","",ROUND(AVERAGE(G50,J50,M50,P50,S50,V50,Y50,AB50,AE50,AH50,AK50,AN50,AQ50,AT50),0))
A51: 40 | G51: =IF(E51="","",MAX(E51:F51)) | J51: =IF(H51="","",MAX(H51:I51)) | M51: =IF(K51="","",MAX(K51:L51)) | P51: =IF(N51="","",MAX(N51:O51)) | S51: =IF(Q51="","",MAX(Q51:R51)) | V51: =IF(T51="","",MAX(T51:U51)) | Y51: =IF(W51="","",MAX(W51:X51)) | AB51: =IF(Z51="","",MAX(Z51:AA51)) | AE51: =IF(AC51="","",MAX(AC51:AD51)) | AH51: =IF(AF51="","",MAX(AF51:AG51)) | AK51: =IF(AI51="","",MAX(AI51:AJ51)) | AN51: =IF(AL51="","",MAX(AL51:AM51)) | AQ51: =IF(AO51="","",MAX(AO51:AP51)) | AT51: =IF(AR51="","",MAX(AR51:AS51)) | AU51: =IF(E51="","",ROUND(AVERAGE(G51,J51,M51,P51,S51,V51,Y51,AB51,AE51,AH51,AK51,AN51,AQ51,AT51),0))
A53: Keterangan :
A54: 1 | B54: Isian ini digunakan untuk membantu mengisi penilaian pengetahuan | N54: Banjarbaru, Agustus 2025
A55: 2 | B55: Isikan hasil penilaian harian sesuai dengan kompetensi dasar (0 - 100) | N55: Guru Mata Pelajaran
A56: 3 | B56: NS : Nilai Semula | D56: NH : Nilai Harian
B57: R : Nilai Remedial | D57: UTS : Nilai UTS
B58: NA : Nilai Akhir KD | D58: UAS : Nilai UAS
A60: Copyright Ó SMKTelkom SP – Juli 2014 Ver 1.0

Sheet Rekap Pengetahuan
A8: NO | B8: NILAI KOMPETENSI DASAR PADA KI-3 | Q8: NILAI UUS | S8: NA | T8: NR | U8: Predikat | V8: Yang menonjol | X8: Yang kurang | Z8: DESKRIPSI
B9: =IF('Pengetahuan (rincian)'!E10="","",'Pengetahuan (rincian)'!E10) -> Memahami konsep dasar basis data | C9: =IF('Pengetahuan (rincian)'!H10="","",'Pengetahuan (rincian)'!H10) -> Mendeskripsikan Model Data dan Hubungan Antar Entitas | D9: =IF('Pengetahuan (rincian)'!K10="","",'Pengetahuan (rincian)'!K10) -> Mengimplementasikan Relasi Data | E9: =IF('Pengetahuan (rincian)'!N10="","",'Pengetahuan (rincian)'!N10) | F9: =IF('Pengetahuan (rincian)'!Q10="","",'Pengetahuan (rincian)'!Q10) | G9: =IF('Pengetahuan (rincian)'!T10="","",'Pengetahuan (rincian)'!T10) | H9: =IF('Pengetahuan (rincian)'!W10="","",'Pengetahuan (rincian)'!W10) | I9: =IF('Pengetahuan (rincian)'!Z10="","",'Pengetahuan (rincian)'!Z10) | J9: =IF('Pengetahuan (rincian)'!AC10="","",'Pengetahuan (rincian)'!AC10) | K9: =IF('Pengetahuan (rincian)'!AF10="","",'Pengetahuan (rincian)'!AF10) | L9: =IF('Pengetahuan (rincian)'!AI10="","",'Pengetahuan (rincian)'!AI10) | M9: =IF('Pengetahuan (rincian)'!AL10="","",'Pengetahuan (rincian)'!AL10) | N9: =IF('Pengetahuan (rincian)'!AO10="","",'Pengetahuan (rincian)'!AO10) | O9: =IF('Pengetahuan (rincian)'!AR10="","",'Pengetahuan (rincian)'!AR10) | P9: NH | Q9: UTS | R9: UAS
B10: NA | C10: NA | D10: NA | E10: NA | F10: NA | G10: NA | H10: NA | I10: NA | J10: NA | K10: NA | L10: NA | M10: NA | N10: NA | O10: NA | Q10: NA | R10: NA
A11: 1 | B11: =IF('Pengetahuan (rincian)'!G12="","",'Pengetahuan (rincian)'!G12) -> 90 | C11: =IF('Pengetahuan (rincian)'!J12="","",'Pengetahuan (rincian)'!J12) -> 80 | D11: =IF('Pengetahuan (rincian)'!M12="","",'Pengetahuan (rincian)'!M12) -> 90 | E11: =IF('Pengetahuan (rincian)'!P12="","",'Pengetahuan (rincian)'!P12) | F11: =IF('Pengetahuan (rincian)'!S12="","",'Pengetahuan (rincian)'!S12) | G11: =IF('Pengetahuan (rincian)'!V12="","",'Pengetahuan (rincian)'!V12) | H11: =IF('Pengetahuan (rincian)'!Y12="","",'Pengetahuan (rincian)'!Y12) | I11: =IF('Pengetahuan (rincian)'!AB12="","",'Pengetahuan (rincian)'!AB12) | J11: =IF('Pengetahuan (rincian)'!AE12="","",'Pengetahuan (rincian)'!AE12) | K11: =IF('Pengetahuan (rincian)'!AH12="","",'Pengetahuan (rincian)'!AH12) | L11: =IF('Pengetahuan (rincian)'!AK12="","",'Pengetahuan (rincian)'!AK12) | M11: =IF('Pengetahuan (rincian)'!AN12="","",'Pengetahuan (rincian)'!AN12) | N11: =IF('Pengetahuan (rincian)'!AQ12="","",'Pengetahuan (rincian)'!AQ12) | O11: =IF('Pengetahuan (rincian)'!AT12="","",'Pengetahuan (rincian)'!AT12) | P11: =IF(B11="","",ROUND(AVERAGE(B11:O11),0)) -> 87 | Q11: =IF('Pengetahuan (rincian)'!AV12="","",ROUND(MAX('Pengetahuan (rincian)'!AV12:AW12),0)) -> 80 | R11: =IF('Pengetahuan (rincian)'!AX12="","",ROUND(MAX('Pengetahuan (rincian)'!AX12:AY12),0)) -> 90 | S11: =IF(P11="","",ROUND((3*P11+Q11+R11)/5,0)) -> 86 | T11: =IF(S11="","",IF(S11>=96,4,IF(S11>=91,3.66,IF(S11>=86,3.33,IF(S11>=81,3,IF(S11>=75,2.66,IF(S11>=70,2.33,IF(S11>=65,2,IF(S11>=60,1.66,IF(S11>=55,1.33,1)))))))))) -> 3.33 | U11: =IF(T11="","",IF(T11=4,"A",IF(T11=3.66,"A-",IF(T11=3.33,"B+",IF(T11=3,"B",IF(T11=2.66,"B-",IF(T11=2.33,"C+",IF(T11=2,"C",IF(T11=1.66,"C-",IF(T11=1.33,"D+","D")))))))))) -> B+ | V11: =MAX(B11:G11) -> 90 | W11: =INDEX($B$9:$O$9,1,MATCH(MAX(B11:O11),B11:O11,0)) -> Memahami konsep dasar basis data | X11: =MIN(B11:O11) -> 80 | Y11: =INDEX($B$9:$O$9,1,MATCH(MIN(B11:O11),B11:O11,0)) -> Mendeskripsikan Model Data dan Hubungan Antar Entitas | Z11: =IF(OR(U11="C+",U11="C",U11="C-",U11="D+",U11="D"),CONCATENATE("Belum memahami sebagian besar kompetensi, terutama kurang dalam ",Y11),IF(OR(U11="A",U11="A-"),CONCATENATE("Sudah memahami seluruh kompetensi, terutama sangat baik dalam ",W11),IF(OR(U11="B+",U11="B",U11="B-"),CONCATENATE(IF(X11<80,CONCATENATE("Sudah memahami sebagian besar kompetensi, terutama dalam ",W11,", namun dalam ",Y11," perlu ditingkatkan"),CONCATENATE("Sudah memahami seluruh kompetensi, terutama dalam ",W11)),"")))) -> Sudah memahami seluruh kompetensi, terutama dalam Memahami konsep dasar basis data
A12: 2 | B12: =IF('Pengetahuan (rincian)'!G13="","",'Pengetahuan (rincian)'!G13) -> 90 | C12: =IF('Pengetahuan (rincian)'!J13="","",'Pengetahuan (rincian)'!J13) -> 80 | D12: =IF('Pengetahuan (rincian)'!M13="","",'Pengetahuan (rincian)'!M13) -> 90 | E12: =IF('Pengetahuan (rincian)'!P13="","",'Pengetahuan (rincian)'!P13) | F12: =IF('Pengetahuan (rincian)'!S13="","",'Pengetahuan (rincian)'!S13) | G12: =IF('Pengetahuan (rincian)'!V13="","",'Pengetahuan (rincian)'!V13) | H12: =IF('Pengetahuan (rincian)'!Y13="","",'Pengetahuan (rincian)'!Y13) | I12: =IF('Pengetahuan (rincian)'!AB13="","",'Pengetahuan (rincian)'!AB13) | J12: =IF('Pengetahuan (rincian)'!AE13="","",'Pengetahuan (rincian)'!AE13) | K12: =IF('Pengetahuan (rincian)'!AH13="","",'Pengetahuan (rincian)'!AH13) | L12: =IF('Pengetahuan (rincian)'!AK13="","",'Pengetahuan (rincian)'!AK13) | M12: =IF('Pengetahuan (rincian)'!AN13="","",'Pengetahuan (rincian)'!AN13) | N12: =IF('Pengetahuan (rincian)'!AQ13="","",'Pengetahuan (rincian)'!AQ13) | O12: =IF('Pengetahuan (rincian)'!AT13="","",'Pengetahuan (rincian)'!AT13) | P12: =IF(B12="","",ROUND(AVERAGE(B12:O12),0)) -> 87 | Q12: =IF('Pengetahuan (rincian)'!AV13="","",ROUND(MAX('Pengetahuan (rincian)'!AV13:AW13),0)) -> 80 | R12: =IF('Pengetahuan (rincian)'!AX13="","",ROUND(MAX('Pengetahuan (rincian)'!AX13:AY13),0)) -> 90 | S12: =IF(P12="","",ROUND((3*P12+Q12+R12)/5,0)) -> 86 | T12: =IF(S12="","",IF(S12>=96,4,IF(S12>=91,3.66,IF(S12>=86,3.33,IF(S12>=81,3,IF(S12>=75,2.66,IF(S12>=70,2.33,IF(S12>=65,2,IF(S12>=60,1.66,IF(S12>=55,1.33,1)))))))))) -> 3.33 | U12: =IF(T12="","",IF(T12=4,"A",IF(T12=3.66,"A-",IF(T12=3.33,"B+",IF(T12=3,"B",IF(T12=2.66,"B-",IF(T12=2.33,"C+",IF(T12=2,"C",IF(T12=1.66,"C-",IF(T12=1.33,"D+","D")))))))))) -> B+ | V12: =MAX(B12:G12) -> 90 | W12: =INDEX($B$9:$O$9,1,MATCH(MAX(B12:O12),B12:O12,0)) -> Memahami konsep dasar basis data | X12: =MIN(B12:O12) -> 80 | Y12: =INDEX($B$9:$O$9,1,MATCH(MIN(B12:O12),B12:O12,0)) -> Mendeskripsikan Model Data dan Hubungan Antar Entitas | Z12: =IF(OR(U12="C+",U12="C",U12="C-",U12="D+",U12="D"),CONCATENATE("Belum memahami sebagian besar kompetensi, terutama kurang dalam ",Y12),IF(OR(U12="A",U12="A-"),CONCATENATE("Sudah memahami seluruh kompetensi, terutama sangat baik dalam ",W12),IF(OR(U12="B+",U12="B",U12="B-"),CONCATENATE(IF(X12<80,CONCATENATE("Sudah memahami sebagian besar kompetensi, terutama dalam ",W12,", namun dalam ",Y12," perlu ditingkatkan"),CONCATENATE("Sudah memahami seluruh kompetensi, terutama dalam ",W12)),"")))) -> Sudah memahami seluruh kompetensi, terutama dalam Memahami konsep dasar basis data
A13: 3 | B13: =IF('Pengetahuan (rincian)'!G14="","",'Pengetahuan (rincian)'!G14) -> 92 | C13: =IF('Pengetahuan (rincian)'!J14="","",'Pengetahuan (rincian)'!J14) -> 95 | D13: =IF('Pengetahuan (rincian)'!M14="","",'Pengetahuan (rincian)'!M14) -> 92 | E13: =IF('Pengetahuan (rincian)'!P14="","",'Pengetahuan (rincian)'!P14) | F13: =IF('Pengetahuan (rincian)'!S14="","",'Pengetahuan (rincian)'!S14) | G13: =IF('Pengetahuan (rincian)'!V14="","",'Pengetahuan (rincian)'!V14) | H13: =IF('Pengetahuan (rincian)'!Y14="","",'Pengetahuan (rincian)'!Y14) | I13: =IF('Pengetahuan (rincian)'!AB14="","",'Pengetahuan (rincian)'!AB14) | J13: =IF('Pengetahuan (rincian)'!AE14="","",'Pengetahuan (rincian)'!AE14) | K13: =IF('Pengetahuan (rincian)'!AH14="","",'Pengetahuan (rincian)'!AH14) | L13: =IF('Pengetahuan (rincian)'!AK14="","",'Pengetahuan (rincian)'!AK14) | M13: =IF('Pengetahuan (rincian)'!AN14="","",'Pengetahuan (rincian)'!AN14) | N13: =IF('Pengetahuan (rincian)'!AQ14="","",'Pengetahuan (rincian)'!AQ14) | O13: =IF('Pengetahuan (rincian)'!AT14="","",'Pengetahuan (rincian)'!AT14) | P13: =IF(B13="","",ROUND(AVERAGE(B13:O13),0)) -> 93 | Q13: =IF('Pengetahuan (rincian)'!AV14="","",ROUND(MAX('Pengetahuan (rincian)'!AV14:AW14),0)) -> 95 | R13: =IF('Pengetahuan (rincian)'!AX14="","",ROUND(MAX('Pengetahuan (rincian)'!AX14:AY14),0)) -> 92 | S13: =IF(P13="","",ROUND((3*P13+Q13+R13)/5,0)) -> 93 | T13: =IF(S13="","",IF(S13>=96,4,IF(S13>=91,3.66,IF(S13>=86,3.33,IF(S13>=81,3,IF(S13>=75,2.66,IF(S13>=70,2.33,IF(S13>=65,2,IF(S13>=60,1.66,IF(S13>=55,1.33,1)))))))))) -> 3.66 | U13: =IF(T13="","",IF(T13=4,"A",IF(T13=3.66,"A-",IF(T13=3.33,"B+",IF(T13=3,"B",IF(T13=2.66,"B-",IF(T13=2.33,"C+",IF(T13=2,"C",IF(T13=1.66,"C-",IF(T13=1.33,"D+","D")))))))))) -> A- | V13: =MAX(B13:G13) -> 95 | W13: =INDEX($B$9:$O$9,1,MATCH(MAX(B13:O13),B13:O13,0)) -> Mendeskripsikan Model Data dan Hubungan Antar Entitas | X13: =MIN(B13:O13) -> 92 | Y13: =INDEX($B$9:$O$9,1,MATCH(MIN(B13:O13),B13:O13,0)) -> Memahami konsep dasar basis data | Z13: =IF(OR(U13="C+",U13="C",U13="C-",U13="D+",U13="D"),CONCATENATE("Belum memahami sebagian besar kompetensi, terutama kurang dalam ",Y13),IF(OR(U13="A",U13="A-"),CONCATENATE("Sudah memahami seluruh kompetensi, terutama sangat baik dalam ",W13),IF(OR(U13="B+",U13="B",U13="B-"),CONCATENATE(IF(X13<80,CONCATENATE("Sudah memahami sebagian besar kompetensi, terutama dalam ",W13,", namun dalam ",Y13," perlu ditingkatkan"),CONCATENATE("Sudah memahami seluruh kompetensi, terutama dalam ",W13)),"")))) -> Sudah memahami seluruh kompetensi, terutama sangat baik dalam Mendeskripsikan Model Data dan Hubungan Antar Entitas
A14: 4 | B14: =IF('Pengetahuan (rincian)'!G15="","",'Pengetahuan (rincian)'!G15) -> 95 | C14: =IF('Pengetahuan (rincian)'!J15="","",'Pengetahuan (rincian)'!J15) -> 93 | D14: =IF('Pengetahuan (rincian)'!M15="","",'Pengetahuan (rincian)'!M15) -> 95 | E14: =IF('Pengetahuan (rincian)'!P15="","",'Pengetahuan (rincian)'!P15) | F14: =IF('Pengetahuan (rincian)'!S15="","",'Pengetahuan (rincian)'!S15) | G14: =IF('Pengetahuan (rincian)'!V15="","",'Pengetahuan (rincian)'!V15) | H14: =IF('Pengetahuan (rincian)'!Y15="","",'Pengetahuan (rincian)'!Y15) | I14: =IF('Pengetahuan (rincian)'!AB15="","",'Pengetahuan (rincian)'!AB15) | J14: =IF('Pengetahuan (rincian)'!AE15="","",'Pengetahuan (rincian)'!AE15) | K14: =IF('Pengetahuan (rincian)'!AH15="","",'Pengetahuan (rincian)'!AH15) | L14: =IF('Pengetahuan (rincian)'!AK15="","",'Pengetahuan (rincian)'!AK15) | M14: =IF('Pengetahuan (rincian)'!AN15="","",'Pengetahuan (rincian)'!AN15) | N14: =IF('Pengetahuan (rincian)'!AQ15="","",'Pengetahuan (rincian)'!AQ15) | O14: =IF('Pengetahuan (rincian)'!AT15="","",'Pengetahuan (rincian)'!AT15) | P14: =IF(B14="","",ROUND(AVERAGE(B14:O14),0)) -> 94 | Q14: =IF('Pengetahuan (rincian)'!AV15="","",ROUND(MAX('Pengetahuan (rincian)'!AV15:AW15),0)) -> 93 | R14: =IF('Pengetahuan (rincian)'!AX15="","",ROUND(MAX('Pengetahuan (rincian)'!AX15:AY15),0)) -> 95 | S14: =IF(P14="","",ROUND((3*P14+Q14+R14)/5,0)) -> 94 | T14: =IF(S14="","",IF(S14>=96,4,IF(S14>=91,3.66,IF(S14>=86,3.33,IF(S14>=81,3,IF(S14>=75,2.66,IF(S14>=70,2.33,IF(S14>=65,2,IF(S14>=60,1.66,IF(S14>=55,1.33,1)))))))))) -> 3.66 | U14: =IF(T14="","",IF(T14=4,"A",IF(T14=3.66,"A-",IF(T14=3.33,"B+",IF(T14=3,"B",IF(T14=2.66,"B-",IF(T14=2.33,"C+",IF(T14=2,"C",IF(T14=1.66,"C-",IF(T14=1.33,"D+","D")))))))))) -> A- | V14: =MAX(B14:G14) -> 95 | W14: =INDEX($B$9:$O$9,1,MATCH(MAX(B14:O14),B14:O14,0)) -> Memahami konsep dasar basis data | X14: =MIN(B14:O14) -> 93 | Y14: =INDEX($B$9:$O$9,1,MATCH(MIN(B14:O14),B14:O14,0)) -> Mendeskripsikan Model Data dan Hubungan Antar Entitas | Z14: =IF(OR(U14="C+",U14="C",U14="C-",U14="D+",U14="D"),CONCATENATE("Belum memahami sebagian besar kompetensi, terutama kurang dalam ",Y14),IF(OR(U14="A",U14="A-"),CONCATENATE("Sudah memahami seluruh kompetensi, terutama sangat baik dalam ",W14),IF(OR(U14="B+",U14="B",U14="B-"),CONCATENATE(IF(X14<80,CONCATENATE("Sudah memahami sebagian besar kompetensi, terutama dalam ",W14,", namun dalam ",Y14," perlu ditingkatkan"),CONCATENATE("Sudah memahami seluruh kompetensi, terutama dalam ",W14)),"")))) -> Sudah memahami seluruh kompetensi, terutama sangat baik dalam Memahami konsep dasar basis data
A15: 5 | B15: =IF('Pengetahuan (rincian)'!G16="","",'Pengetahuan (rincian)'!G16) -> 92 | C15: =IF('Pengetahuan (rincian)'!J16="","",'Pengetahuan (rincian)'!J16) -> 95 | D15: =IF('Pengetahuan (rincian)'!M16="","",'Pengetahuan (rincian)'!M16) -> 92 | E15: =IF('Pengetahuan (rincian)'!P16="","",'Pengetahuan (rincian)'!P16) | F15: =IF('Pengetahuan (rincian)'!S16="","",'Pengetahuan (rincian)'!S16) | G15: =IF('Pengetahuan (rincian)'!V16="","",'Pengetahuan (rincian)'!V16) | H15: =IF('Pengetahuan (rincian)'!Y16="","",'Pengetahuan (rincian)'!Y16) | I15: =IF('Pengetahuan (rincian)'!AB16="","",'Pengetahuan (rincian)'!AB16) | J15: =IF('Pengetahuan (rincian)'!AE16="","",'Pengetahuan (rincian)'!AE16) | K15: =IF('Pengetahuan (rincian)'!AH16="","",'Pengetahuan (rincian)'!AH16) | L15: =IF('Pengetahuan (rincian)'!AK16="","",'Pengetahuan (rincian)'!AK16) | M15: =IF('Pengetahuan (rincian)'!AN16="","",'Pengetahuan (rincian)'!AN16) | N15: =IF('Pengetahuan (rincian)'!AQ16="","",'Pengetahuan (rincian)'!AQ16) | O15: =IF('Pengetahuan (rincian)'!AT16="","",'Pengetahuan (rincian)'!AT16) | P15: =IF(B15="","",ROUND(AVERAGE(B15:O15),0)) -> 93 | Q15: =IF('Pengetahuan (rincian)'!AV16="","",ROUND(MAX('Pengetahuan (rincian)'!AV16:AW16),0)) -> 95 | R15: =IF('Pengetahuan (rincian)'!AX16="","",ROUND(MAX('Pengetahuan (rincian)'!AX16:AY16),0)) -> 92 | S15: =IF(P15="","",ROUND((3*P15+Q15+R15)/5,0)) -> 93 | T15: =IF(S15="","",IF(S15>=96,4,IF(S15>=91,3.66,IF(S15>=86,3.33,IF(S15>=81,3,IF(S15>=75,2.66,IF(S15>=70,2.33,IF(S15>=65,2,IF(S15>=60,1.66,IF(S15>=55,1.33,1)))))))))) -> 3.66 | U15: =IF(T15="","",IF(T15=4,"A",IF(T15=3.66,"A-",IF(T15=3.33,"B+",IF(T15=3,"B",IF(T15=2.66,"B-",IF(T15=2.33,"C+",IF(T15=2,"C",IF(T15=1.66,"C-",IF(T15=1.33,"D+","D")))))))))) -> A- | V15: =MAX(B15:G15) -> 95 | W15: =INDEX($B$9:$O$9,1,MATCH(MAX(B15:O15),B15:O15,0)) -> Mendeskripsikan Model Data dan Hubungan Antar Entitas | X15: =MIN(B15:O15) -> 92 | Y15: =INDEX($B$9:$O$9,1,MATCH(MIN(B15:O15),B15:O15,0)) -> Memahami konsep dasar basis data | Z15: =IF(OR(U15="C+",U15="C",U15="C-",U15="D+",U15="D"),CONCATENATE("Belum memahami sebagian besar kompetensi, terutama kurang dalam ",Y15),IF(OR(U15="A",U15="A-"),CONCATENATE("Sudah memahami seluruh kompetensi, terutama sangat baik dalam ",W15),IF(OR(U15="B+",U15="B",U15="B-"),CONCATENATE(IF(X15<80,CONCATENATE("Sudah memahami sebagian besar kompetensi, terutama dalam ",W15,", namun dalam ",Y15," perlu ditingkatkan"),CONCATENATE("Sudah memahami seluruh kompetensi, terutama dalam ",W15)),"")))) -> Sudah memahami seluruh kompetensi, terutama sangat baik dalam Mendeskripsikan Model Data dan Hubungan Antar Entitas
A16: 6 | B16: =IF('Pengetahuan (rincian)'!G17="","",'Pengetahuan (rincian)'!G17) -> 95 | C16: =IF('Pengetahuan (rincian)'!J17="","",'Pengetahuan (rincian)'!J17) -> 93 | D16: =IF('Pengetahuan (rincian)'!M17="","",'Pengetahuan (rincian)'!M17) -> 95 | E16: =IF('Pengetahuan (rincian)'!P17="","",'Pengetahuan (rincian)'!P17) | F16: =IF('Pengetahuan (rincian)'!S17="","",'Pengetahuan (rincian)'!S17) | G16: =IF('Pengetahuan (rincian)'!V17="","",'Pengetahuan (rincian)'!V17) | H16: =IF('Pengetahuan (rincian)'!Y17="","",'Pengetahuan (rincian)'!Y17) | I16: =IF('Pengetahuan (rincian)'!AB17="","",'Pengetahuan (rincian)'!AB17) | J16: =IF('Pengetahuan (rincian)'!AE17="","",'Pengetahuan (rincian)'!AE17) | K16: =IF('Pengetahuan (rincian)'!AH17="","",'Pengetahuan (rincian)'!AH17) | L16: =IF('Pengetahuan (rincian)'!AK17="","",'Pengetahuan (rincian)'!AK17) | M16: =IF('Pengetahuan (rincian)'!AN17="","",'Pengetahuan (rincian)'!AN17) | N16: =IF('Pengetahuan (rincian)'!AQ17="","",'Pengetahuan (rincian)'!AQ17) | O16: =IF('Pengetahuan (rincian)'!AT17="","",'Pengetahuan (rincian)'!AT17) | P16: =IF(B16="","",ROUND(AVERAGE(B16:O16),0)) -> 94 | Q16: =IF('Pengetahuan (rincian)'!AV17="","",ROUND(MAX('Pengetahuan (rincian)'!AV17:AW17),0)) -> 93 | R16: =IF('Pengetahuan (rincian)'!AX17="","",ROUND(MAX('Pengetahuan (rincian)'!AX17:AY17),0)) -> 95 | S16: =IF(P16="","",ROUND((3*P16+Q16+R16)/5,0)) -> 94 | T16: =IF(S16="","",IF(S16>=96,4,IF(S16>=91,3.66,IF(S16>=86,3.33,IF(S16>=81,3,IF(S16>=75,2.66,IF(S16>=70,2.33,IF(S16>=65,2,IF(S16>=60,1.66,IF(S16>=55,1.33,1)))))))))) -> 3.66 | U16: =IF(T16="","",IF(T16=4,"A",IF(T16=3.66,"A-",IF(T16=3.33,"B+",IF(T16=3,"B",IF(T16=2.66,"B-",IF(T16=2.33,"C+",IF(T16=2,"C",IF(T16=1.66,"C-",IF(T16=1.33,"D+","D")))))))))) -> A- | V16: =MAX(B16:G16) -> 95 | W16: =INDEX($B$9:$O$9,1,MATCH(MAX(B16:O16),B16:O16,0)) -> Memahami konsep dasar basis data | X16: =MIN(B16:O16) -> 93 | Y16: =INDEX($B$9:$O$9,1,MATCH(MIN(B16:O16),B16:O16,0)) -> Mendeskripsikan Model Data dan Hubungan Antar Entitas | Z16: =IF(OR(U16="C+",U16="C",U16="C-",U16="D+",U16="D"),CONCATENATE("Belum memahami sebagian besar kompetensi, terutama kurang dalam ",Y16),IF(OR(U16="A",U16="A-"),CONCATENATE("Sudah memahami seluruh kompetensi, terutama sangat baik dalam ",W16),IF(OR(U16="B+",U16="B",U16="B-"),CONCATENATE(IF(X16<80,CONCATENATE("Sudah memahami sebagian besar kompetensi, terutama dalam ",W16,", namun dalam ",Y16," perlu ditingkatkan"),CONCATENATE("Sudah memahami seluruh kompetensi, terutama dalam ",W16)),"")))) -> Sudah memahami seluruh kompetensi, terutama sangat baik dalam Memahami konsep dasar basis data
A17: 7 | B17: =IF('Pengetahuan (rincian)'!G18="","",'Pengetahuan (rincian)'!G18) -> 90 | C17: =IF('Pengetahuan (rincian)'!J18="","",'Pengetahuan (rincian)'!J18) -> 95 | D17: =IF('Pengetahuan (rincian)'!M18="","",'Pengetahuan (rincian)'!M18) -> 90 | E17: =IF('Pengetahuan (rincian)'!P18="","",'Pengetahuan (rincian)'!P18) | F17: =IF('Pengetahuan (rincian)'!S18="","",'Pengetahuan (rincian)'!S18) | G17: =IF('Pengetahuan (rincian)'!V18="","",'Pengetahuan (rincian)'!V18) | H17: =IF('Pengetahuan (rincian)'!Y18="","",'Pengetahuan (rincian)'!Y18) | I17: =IF('Pengetahuan (rincian)'!AB18="","",'Pengetahuan (rincian)'!AB18) | J17: =IF('Pengetahuan (rincian)'!AE18="","",'Pengetahuan (rincian)'!AE18) | K17: =IF('Pengetahuan (rincian)'!AH18="","",'Pengetahuan (rincian)'!AH18) | L17: =IF('Pengetahuan (rincian)'!AK18="","",'Pengetahuan (rincian)'!AK18) | M17: =IF('Pengetahuan (rincian)'!AN18="","",'Pengetahuan (rincian)'!AN18) | N17: =IF('Pengetahuan (rincian)'!AQ18="","",'Pengetahuan (rincian)'!AQ18) | O17: =IF('Pengetahuan (rincian)'!AT18="","",'Pengetahuan (rincian)'!AT18) | P17: =IF(B17="","",ROUND(AVERAGE(B17:O17),0)) -> 92 | Q17: =IF('Pengetahuan (rincian)'!AV18="","",ROUND(MAX('Pengetahuan (rincian)'!AV18:AW18),0)) -> 95 | R17: =IF('Pengetahuan (rincian)'!AX18="","",ROUND(MAX('Pengetahuan (rincian)'!AX18:AY18),0)) -> 90 | S17: =IF(P17="","",ROUND((3*P17+Q17+R17)/5,0)) -> 92 | T17: =IF(S17="","",IF(S17>=96,4,IF(S17>=91,3.66,IF(S17>=86,3.33,IF(S17>=81,3,IF(S17>=75,2.66,IF(S17>=70,2.33,IF(S17>=65,2,IF(S17>=60,1.66,IF(S17>=55,1.33,1)))))))))) -> 3.66 | U17: =IF(T17="","",IF(T17=4,"A",IF(T17=3.66,"A-",IF(T17=3.33,"B+",IF(T17=3,"B",IF(T17=2.66,"B-",IF(T17=2.33,"C+",IF(T17=2,"C",IF(T17=1.66,"C-",IF(T17=1.33,"D+","D")))))))))) -> A- | V17: =MAX(B17:G17) -> 95 | W17: =INDEX($B$9:$O$9,1,MATCH(MAX(B17:O17),B17:O17,0)) -> Mendeskripsikan Model Data dan Hubungan Antar Entitas | X17: =MIN(B17:O17) -> 90 | Y17: =INDEX($B$9:$O$9,1,MATCH(MIN(B17:O17),B17:O17,0)) -> Memahami konsep dasar basis data | Z17: =IF(OR(U17="C+",U17="C",U17="C-",U17="D+",U17="D"),CONCATENATE("Belum memahami sebagian besar kompetensi, terutama kurang dalam ",Y17),IF(OR(U17="A",U17="A-"),CONCATENATE("Sudah memahami seluruh kompetensi, terutama sangat baik dalam ",W17),IF(OR(U17="B+",U17="B",U17="B-"),CONCATENATE(IF(X17<80,CONCATENATE("Sudah memahami sebagian besar kompetensi, terutama dalam ",W17,", namun dalam ",Y17," perlu ditingkatkan"),CONCATENATE("Sudah memahami seluruh kompetensi, terutama dalam ",W17)),"")))) -> Sudah memahami seluruh kompetensi, terutama sangat baik dalam Mendeskripsikan Model Data dan Hubungan Antar Entitas
A18: 8 | B18: =IF('Pengetahuan (rincian)'!G19="","",'Pengetahuan (rincian)'!G19) -> 88 | C18: =IF('Pengetahuan (rincian)'!J19="","",'Pengetahuan (rincian)'!J19) -> 95 | D18: =IF('Pengetahuan (rincian)'!M19="","",'Pengetahuan (rincian)'!M19) -> 88 | E18: =IF('Pengetahuan (rincian)'!P19="","",'Pengetahuan (rincian)'!P19) | F18: =IF('Pengetahuan (rincian)'!S19="","",'Pengetahuan (rincian)'!S19) | G18: =IF('Pengetahuan (rincian)'!V19="","",'Pengetahuan (rincian)'!V19) | H18: =IF('Pengetahuan (rincian)'!Y19="","",'Pengetahuan (rincian)'!Y19) | I18: =IF('Pengetahuan (rincian)'!AB19="","",'Pengetahuan (rincian)'!AB19) | J18: =IF('Pengetahuan (rincian)'!AE19="","",'Pengetahuan (rincian)'!AE19) | K18: =IF('Pengetahuan (rincian)'!AH19="","",'Pengetahuan (rincian)'!AH19) | L18: =IF('Pengetahuan (rincian)'!AK19="","",'Pengetahuan (rincian)'!AK19) | M18: =IF('Pengetahuan (rincian)'!AN19="","",'Pengetahuan (rincian)'!AN19) | N18: =IF('Pengetahuan (rincian)'!AQ19="","",'Pengetahuan (rincian)'!AQ19) | O18: =IF('Pengetahuan (rincian)'!AT19="","",'Pengetahuan (rincian)'!AT19) | P18: =IF(B18="","",ROUND(AVERAGE(B18:O18),0)) -> 90 | Q18: =IF('Pengetahuan (rincian)'!AV19="","",ROUND(MAX('Pengetahuan (rincian)'!AV19:AW19),0)) -> 95 | R18: =IF('Pengetahuan (rincian)'!AX19="","",ROUND(MAX('Pengetahuan (rincian)'!AX19:AY19),0)) -> 88 | S18: =IF(P18="","",ROUND((3*P18+Q18+R18)/5,0)) -> 91 | T18: =IF(S18="","",IF(S18>=96,4,IF(S18>=91,3.66,IF(S18>=86,3.33,IF(S18>=81,3,IF(S18>=75,2.66,IF(S18>=70,2.33,IF(S18>=65,2,IF(S18>=60,1.66,IF(S18>=55,1.33,1)))))))))) -> 3.66 | U18: =IF(T18="","",IF(T18=4,"A",IF(T18=3.66,"A-",IF(T18=3.33,"B+",IF(T18=3,"B",IF(T18=2.66,"B-",IF(T18=2.33,"C+",IF(T18=2,"C",IF(T18=1.66,"C-",IF(T18=1.33,"D+","D")))))))))) -> A- | V18: =MAX(B18:G18) -> 95 | W18: =INDEX($B$9:$O$9,1,MATCH(MAX(B18:O18),B18:O18,0)) -> Mendeskripsikan Model Data dan Hubungan Antar Entitas | X18: =MIN(B18:O18) -> 88 | Y18: =INDEX($B$9:$O$9,1,MATCH(MIN(B18:O18),B18:O18,0)) -> Memahami konsep dasar basis data | Z18: =IF(OR(U18="C+",U18="C",U18="C-",U18="D+",U18="D"),CONCATENATE("Belum memahami sebagian besar kompetensi, terutama kurang dalam ",Y18),IF(OR(U18="A",U18="A-"),CONCATENATE("Sudah memahami seluruh kompetensi, terutama sangat baik dalam ",W18),IF(OR(U18="B+",U18="B",U18="B-"),CONCATENATE(IF(X18<80,CONCATENATE("Sudah memahami sebagian besar kompetensi, terutama dalam ",W18,", namun dalam ",Y18," perlu ditingkatkan"),CONCATENATE("Sudah memahami seluruh kompetensi, terutama dalam ",W18)),"")))) -> Sudah memahami seluruh kompetensi, terutama sangat baik dalam Mendeskripsikan Model Data dan Hubungan Antar Entitas
A19: 9 | B19: =IF('Pengetahuan (rincian)'!G20="","",'Pengetahuan (rincian)'!G20) -> 88 | C19: =IF('Pengetahuan (rincian)'!J20="","",'Pengetahuan (rincian)'!J20) -> 95 | D19: =IF('Pengetahuan (rincian)'!M20="","",'Pengetahuan (rincian)'!M20) -> 88 | E19: =IF('Pengetahuan (rincian)'!P20="","",'Pengetahuan (rincian)'!P20) | F19: =IF('Pengetahuan (rincian)'!S20="","",'Pengetahuan (rincian)'!S20) | G19: =IF('Pengetahuan (rincian)'!V20="","",'Pengetahuan (rincian)'!V20) | H19: =IF('Pengetahuan (rincian)'!Y20="","",'Pengetahuan (rincian)'!Y20) | I19: =IF('Pengetahuan (rincian)'!AB20="","",'Pengetahuan (rincian)'!AB20) | J19: =IF('Pengetahuan (rincian)'!AE20="","",'Pengetahuan (rincian)'!AE20) | K19: =IF('Pengetahuan (rincian)'!AH20="","",'Pengetahuan (rincian)'!AH20) | L19: =IF('Pengetahuan (rincian)'!AK20="","",'Pengetahuan (rincian)'!AK20) | M19: =IF('Pengetahuan (rincian)'!AN20="","",'Pengetahuan (rincian)'!AN20) | N19: =IF('Pengetahuan (rincian)'!AQ20="","",'Pengetahuan (rincian)'!AQ20) | O19: =IF('Pengetahuan (rincian)'!AT20="","",'Pengetahuan (rincian)'!AT20) | P19: =IF(B19="","",ROUND(AVERAGE(B19:O19),0)) -> 90 | Q19: =IF('Pengetahuan (rincian)'!AV20="","",ROUND(MAX('Pengetahuan (rincian)'!AV20:AW20),0)) -> 95 | R19: =IF('Pengetahuan (rincian)'!AX20="","",ROUND(MAX('Pengetahuan (rincian)'!AX20:AY20),0)) -> 88 | S19: =IF(P19="","",ROUND((3*P19+Q19+R19)/5,0)) -> 91 | T19: =IF(S19="","",IF(S19>=96,4,IF(S19>=91,3.66,IF(S19>=86,3.33,IF(S19>=81,3,IF(S19>=75,2.66,IF(S19>=70,2.33,IF(S19>=65,2,IF(S19>=60,1.66,IF(S19>=55,1.33,1)))))))))) -> 3.66 | U19: =IF(T19="","",IF(T19=4,"A",IF(T19=3.66,"A-",IF(T19=3.33,"B+",IF(T19=3,"B",IF(T19=2.66,"B-",IF(T19=2.33,"C+",IF(T19=2,"C",IF(T19=1.66,"C-",IF(T19=1.33,"D+","D")))))))))) -> A- | V19: =MAX(B19:G19) -> 95 | W19: =INDEX($B$9:$O$9,1,MATCH(MAX(B19:O19),B19:O19,0)) -> Mendeskripsikan Model Data dan Hubungan Antar Entitas | X19: =MIN(B19:O19) -> 88 | Y19: =INDEX($B$9:$O$9,1,MATCH(MIN(B19:O19),B19:O19,0)) -> Memahami konsep dasar basis data | Z19: =IF(OR(U19="C+",U19="C",U19="C-",U19="D+",U19="D"),CONCATENATE("Belum memahami sebagian besar kompetensi, terutama kurang dalam ",Y19),IF(OR(U19="A",U19="A-"),CONCATENATE("Sudah memahami seluruh kompetensi, terutama sangat baik dalam ",W19),IF(OR(U19="B+",U19="B",U19="B-"),CONCATENATE(IF(X19<80,CONCATENATE("Sudah memahami sebagian besar kompetensi, terutama dalam ",W19,", namun dalam ",Y19," perlu ditingkatkan"),CONCATENATE("Sudah memahami seluruh kompetensi, terutama dalam ",W19)),"")))) -> Sudah memahami seluruh kompetensi, terutama sangat baik dalam Mendeskripsikan Model Data dan Hubungan Antar Entitas
A20: 10 | B20: =IF('Pengetahuan (rincian)'!G21="","",'Pengetahuan (rincian)'!G21) -> 95 | C20: =IF('Pengetahuan (rincian)'!J21="","",'Pengetahuan (rincian)'!J21) -> 90 | D20: =IF('Pengetahuan (rincian)'!M21="","",'Pengetahuan (rincian)'!M21) -> 95 | E20: =IF('Pengetahuan (rincian)'!P21="","",'Pengetahuan (rincian)'!P21) | F20: =IF('Pengetahuan (rincian)'!S21="","",'Pengetahuan (rincian)'!S21) | G20: =IF('Pengetahuan (rincian)'!V21="","",'Pengetahuan (rincian)'!V21) | H20: =IF('Pengetahuan (rincian)'!Y21="","",'Pengetahuan (rincian)'!Y21) | I20: =IF('Pengetahuan (rincian)'!AB21="","",'Pengetahuan (rincian)'!AB21) | J20: =IF('Pengetahuan (rincian)'!AE21="","",'Pengetahuan (rincian)'!AE21) | K20: =IF('Pengetahuan (rincian)'!AH21="","",'Pengetahuan (rincian)'!AH21) | L20: =IF('Pengetahuan (rincian)'!AK21="","",'Pengetahuan (rincian)'!AK21) | M20: =IF('Pengetahuan (rincian)'!AN21="","",'Pengetahuan (rincian)'!AN21) | N20: =IF('Pengetahuan (rincian)'!AQ21="","",'Pengetahuan (rincian)'!AQ21) | O20: =IF('Pengetahuan (rincian)'!AT21="","",'Pengetahuan (rincian)'!AT21) | P20: =IF(B20="","",ROUND(AVERAGE(B20:O20),0)) -> 93 | Q20: =IF('Pengetahuan (rincian)'!AV21="","",ROUND(MAX('Pengetahuan (rincian)'!AV21:AW21),0)) -> 90 | R20: =IF('Pengetahuan (rincian)'!AX21="","",ROUND(MAX('Pengetahuan (rincian)'!AX21:AY21),0)) -> 95 | S20: =IF(P20="","",ROUND((3*P20+Q20+R20)/5,0)) -> 93 | T20: =IF(S20="","",IF(S20>=96,4,IF(S20>=91,3.66,IF(S20>=86,3.33,IF(S20>=81,3,IF(S20>=75,2.66,IF(S20>=70,2.33,IF(S20>=65,2,IF(S20>=60,1.66,IF(S20>=55,1.33,1)))))))))) -> 3.66 | U20: =IF(T20="","",IF(T20=4,"A",IF(T20=3.66,"A-",IF(T20=3.33,"B+",IF(T20=3,"B",IF(T20=2.66,"B-",IF(T20=2.33,"C+",IF(T20=2,"C",IF(T20=1.66,"C-",IF(T20=1.33,"D+","D")))))))))) -> A- | V20: =MAX(B20:G20) -> 95 | W20: =INDEX($B$9:$O$9,1,MATCH(MAX(B20:O20),B20:O20,0)) -> Memahami konsep dasar basis data | X20: =MIN(B20:O20) -> 90 | Y20: =INDEX($B$9:$O$9,1,MATCH(MIN(B20:O20),B20:O20,0)) -> Mendeskripsikan Model Data dan Hubungan Antar Entitas | Z20: =IF(OR(U20="C+",U20="C",U20="C-",U20="D+",U20="D"),CONCATENATE("Belum memahami sebagian besar kompetensi, terutama kurang dalam ",Y20),IF(OR(U20="A",U20="A-"),CONCATENATE("Sudah memahami seluruh kompetensi, terutama sangat baik dalam ",W20),IF(OR(U20="B+",U20="B",U20="B-"),CONCATENATE(IF(X20<80,CONCATENATE("Sudah memahami sebagian besar kompetensi, terutama dalam ",W20,", namun dalam ",Y20," perlu ditingkatkan"),CONCATENATE("Sudah memahami seluruh kompetensi, terutama dalam ",W20)),"")))) -> Sudah memahami seluruh kompetensi, terutama sangat baik dalam Memahami konsep dasar basis data
A21: 11 | B21: =IF('Pengetahuan (rincian)'!G22="","",'Pengetahuan (rincian)'!G22) -> 95 | C21: =IF('Pengetahuan (rincian)'!J22="","",'Pengetahuan (rincian)'!J22) -> 95 | D21: =IF('Pengetahuan (rincian)'!M22="","",'Pengetahuan (rincian)'!M22) -> 95 | E21: =IF('Pengetahuan (rincian)'!P22="","",'Pengetahuan (rincian)'!P22) | F21: =IF('Pengetahuan (rincian)'!S22="","",'Pengetahuan (rincian)'!S22) | G21: =IF('Pengetahuan (rincian)'!V22="","",'Pengetahuan (rincian)'!V22) | H21: =IF('Pengetahuan (rincian)'!Y22="","",'Pengetahuan (rincian)'!Y22) | I21: =IF('Pengetahuan (rincian)'!AB22="","",'Pengetahuan (rincian)'!AB22) | J21: =IF('Pengetahuan (rincian)'!AE22="","",'Pengetahuan (rincian)'!AE22) | K21: =IF('Pengetahuan (rincian)'!AH22="","",'Pengetahuan (rincian)'!AH22) | L21: =IF('Pengetahuan (rincian)'!AK22="","",'Pengetahuan (rincian)'!AK22) | M21: =IF('Pengetahuan (rincian)'!AN22="","",'Pengetahuan (rincian)'!AN22) | N21: =IF('Pengetahuan (rincian)'!AQ22="","",'Pengetahuan (rincian)'!AQ22) | O21: =IF('Pengetahuan (rincian)'!AT22="","",'Pengetahuan (rincian)'!AT22) | P21: =IF(B21="","",ROUND(AVERAGE(B21:O21),0)) -> 95 | Q21: =IF('Pengetahuan (rincian)'!AV22="","",ROUND(MAX('Pengetahuan (rincian)'!AV22:AW22),0)) -> 95 | R21: =IF('Pengetahuan (rincian)'!AX22="","",ROUND(MAX('Pengetahuan (rincian)'!AX22:AY22),0)) -> 95 | S21: =IF(P21="","",ROUND((3*P21+Q21+R21)/5,0)) -> 95 | T21: =IF(S21="","",IF(S21>=96,4,IF(S21>=91,3.66,IF(S21>=86,3.33,IF(S21>=81,3,IF(S21>=75,2.66,IF(S21>=70,2.33,IF(S21>=65,2,IF(S21>=60,1.66,IF(S21>=55,1.33,1)))))))))) -> 3.66 | U21: =IF(T21="","",IF(T21=4,"A",IF(T21=3.66,"A-",IF(T21=3.33,"B+",IF(T21=3,"B",IF(T21=2.66,"B-",IF(T21=2.33,"C+",IF(T21=2,"C",IF(T21=1.66,"C-",IF(T21=1.33,"D+","D")))))))))) -> A- | V21: =MAX(B21:G21) -> 95 | W21: =INDEX($B$9:$O$9,1,MATCH(MAX(B21:O21),B21:O21,0)) -> Memahami konsep dasar basis data | X21: =MIN(B21:O21) -> 95 | Y21: =INDEX($B$9:$O$9,1,MATCH(MIN(B21:O21),B21:O21,0)) -> Memahami konsep dasar basis data | Z21: =IF(OR(U21="C+",U21="C",U21="C-",U21="D+",U21="D"),CONCATENATE("Belum memahami sebagian besar kompetensi, terutama kurang dalam ",Y21),IF(OR(U21="A",U21="A-"),CONCATENATE("Sudah memahami seluruh kompetensi, terutama sangat baik dalam ",W21),IF(OR(U21="B+",U21="B",U21="B-"),CONCATENATE(IF(X21<80,CONCATENATE("Sudah memahami sebagian besar kompetensi, terutama dalam ",W21,", namun dalam ",Y21," perlu ditingkatkan"),CONCATENATE("Sudah memahami seluruh kompetensi, terutama dalam ",W21)),"")))) -> Sudah memahami seluruh kompetensi, terutama sangat baik dalam Memahami konsep dasar basis data
A22: 12 | B22: =IF('Pengetahuan (rincian)'!G23="","",'Pengetahuan (rincian)'!G23) -> 95 | C22: =IF('Pengetahuan (rincian)'!J23="","",'Pengetahuan (rincian)'!J23) -> 90 | D22: =IF('Pengetahuan (rincian)'!M23="","",'Pengetahuan (rincian)'!M23) -> 95 | E22: =IF('Pengetahuan (rincian)'!P23="","",'Pengetahuan (rincian)'!P23) | F22: =IF('Pengetahuan (rincian)'!S23="","",'Pengetahuan (rincian)'!S23) | G22: =IF('Pengetahuan (rincian)'!V23="","",'Pengetahuan (rincian)'!V23) | H22: =IF('Pengetahuan (rincian)'!Y23="","",'Pengetahuan (rincian)'!Y23) | I22: =IF('Pengetahuan (rincian)'!AB23="","",'Pengetahuan (rincian)'!AB23) | J22: =IF('Pengetahuan (rincian)'!AE23="","",'Pengetahuan (rincian)'!AE23) | K22: =IF('Pengetahuan (rincian)'!AH23="","",'Pengetahuan (rincian)'!AH23) | L22: =IF('Pengetahuan (rincian)'!AK23="","",'Pengetahuan (rincian)'!AK23) | M22: =IF('Pengetahuan (rincian)'!AN23="","",'Pengetahuan (rincian)'!AN23) | N22: =IF('Pengetahuan (rincian)'!AQ23="","",'Pengetahuan (rincian)'!AQ23) | O22: =IF('Pengetahuan (rincian)'!AT23="","",'Pengetahuan (rincian)'!AT23) | P22: =IF(B22="","",ROUND(AVERAGE(B22:O22),0)) -> 93 | Q22: =IF('Pengetahuan (rincian)'!AV23="","",ROUND(MAX('Pengetahuan (rincian)'!AV23:AW23),0)) -> 90 | R22: =IF('Pengetahuan (rincian)'!AX23="","",ROUND(MAX('Pengetahuan (rincian)'!AX23:AY23),0)) -> 95 | S22: =IF(P22="","",ROUND((3*P22+Q22+R22)/5,0)) -> 93 | T22: =IF(S22="","",IF(S22>=96,4,IF(S22>=91,3.66,IF(S22>=86,3.33,IF(S22>=81,3,IF(S22>=75,2.66,IF(S22>=70,2.33,IF(S22>=65,2,IF(S22>=60,1.66,IF(S22>=55,1.33,1)))))))))) -> 3.66 | U22: =IF(T22="","",IF(T22=4,"A",IF(T22=3.66,"A-",IF(T22=3.33,"B+",IF(T22=3,"B",IF(T22=2.66,"B-",IF(T22=2.33,"C+",IF(T22=2,"C",IF(T22=1.66,"C-",IF(T22=1.33,"D+","D")))))))))) -> A- | V22: =MAX(B22:G22) -> 95 | W22: =INDEX($B$9:$O$9,1,MATCH(MAX(B22:O22),B22:O22,0)) -> Memahami konsep dasar basis data | X22: =MIN(B22:O22) -> 90 | Y22: =INDEX($B$9:$O$9,1,MATCH(MIN(B22:O22),B22:O22,0)) -> Mendeskripsikan Model Data dan Hubungan Antar Entitas | Z22: =IF(OR(U22="C+",U22="C",U22="C-",U22="D+",U22="D"),CONCATENATE("Belum memahami sebagian besar kompetensi, terutama kurang dalam ",Y22),IF(OR(U22="A",U22="A-"),CONCATENATE("Sudah memahami seluruh kompetensi, terutama sangat baik dalam ",W22),IF(OR(U22="B+",U22="B",U22="B-"),CONCATENATE(IF(X22<80,CONCATENATE("Sudah memahami sebagian besar kompetensi, terutama dalam ",W22,", namun dalam ",Y22," perlu ditingkatkan"),CONCATENATE("Sudah memahami seluruh kompetensi, terutama dalam ",W22)),"")))) -> Sudah memahami seluruh kompetensi, terutama sangat baik dalam Memahami konsep dasar basis data
... A50: 40 | B50: =IF('Pengetahuan (rincian)'!G51="","",'Pengetahuan (rincian)'!G51) | C50: =IF('Pengetahuan (rincian)'!J51="","",'Pengetahuan (rincian)'!J51) | D50: =IF('Pengetahuan (rincian)'!M51="","",'Pengetahuan (rincian)'!M51) | E50: =IF('Pengetahuan (rincian)'!P51="","",'Pengetahuan (rincian)'!P51) | F50: =IF('Pengetahuan (rincian)'!S51="","",'Pengetahuan (rincian)'!S51) | G50: =IF('Pengetahuan (rincian)'!V51="","",'Pengetahuan (rincian)'!V51) | H50: =IF('Pengetahuan (rincian)'!Y51="","",'Pengetahuan (rincian)'!Y51) | I50: =IF('Pengetahuan (rincian)'!AB51="","",'Pengetahuan (rincian)'!AB51) | J50: =IF('Pengetahuan (rincian)'!AE51="","",'Pengetahuan (rincian)'!AE51) | K50: =IF('Pengetahuan (rincian)'!AH51="","",'Pengetahuan (rincian)'!AH51) | L50: =IF('Pengetahuan (rincian)'!AK51="","",'Pengetahuan (rincian)'!AK51) | M50: =IF('Pengetahuan (rincian)'!AN51="","",'Pengetahuan (rincian)'!AN51) | N50: =IF('Pengetahuan (rincian)'!AQ51="","",'Pengetahuan (rincian)'!AQ51) | O50: =IF('Pengetahuan (rincian)'!AT51="","",'Pengetahuan (rincian)'!AT51) | P50: =IF(B50="","",ROUND(AVERAGE(B50:O50),0)) | Q50: =IF('Pengetahuan (rincian)'!AV51="","",ROUND(MAX('Pengetahuan (rincian)'!AV51:AW51),0)) | R50: =IF('Pengetahuan (rincian)'!AX51="","",ROUND(MAX('Pengetahuan (rincian)'!AX51:AY51),0)) | S50: =IF(P50="","",ROUND((3*P50+Q50+R50)/5,0)) | T50: =IF(S50="","",IF(S50>=96,4,IF(S50>=91,3.66,IF(S50>=86,3.33,IF(S50>=81,3,IF(S50>=75,2.66,IF(S50>=70,2.33,IF(S50>=65,2,IF(S50>=60,1.66,IF(S50>=55,1.33,1)))))))))) | U50: =IF(T50="","",IF(T50=4,"A",IF(T50=3.66,"A-",IF(T50=3.33,"B+",IF(T50=3,"B",IF(T50=2.66,"B-",IF(T50=2.33,"C+",IF(T50=2,"C",IF(T50=1.66,"C-",IF(T50=1.33,"D+","D")))))))))) | V50: =MAX(B50:G50) -> 0 | W50: =INDEX($B$9:$O$9,1,MATCH(MAX(B50:O50),B50:O50,0)) -> #N/A | X50: =MIN(B50:O50) -> 0 | Y50: =INDEX($B$9:$O$9,1,MATCH(MIN(B50:O50),B50:O50,0)) -> #N/A | Z50: =IF(OR(U50="C+",U50="C",U50="C-",U50="D+",U50="D"),CONCATENATE("Belum memahami sebagian besar kompetensi, terutama kurang dalam ",Y50),IF(OR(U50="A",U50="A-"),CONCATENATE("Sudah memahami seluruh kompetensi, terutama sangat baik dalam ",W50),IF(OR(U50="B+",U50="B",U50="B-"),CONCATENATE(IF(X50<80,CONCATENATE("Sudah memahami sebagian besar kompetensi, terutama dalam ",W50,", namun dalam ",Y50," perlu ditingkatkan"),CONCATENATE("Sudah memahami seluruh kompetensi, terutama dalam ",W50)),"")))) -> FALSE

Sheet Keterampilan (rincian)
AY1: Confidential
C2: ='Pengetahuan (rincian)'!C2 -> DAFTAR RINCI NILAI PESERTA DIDIK KELAS XIE RPL
C3: ='Pengetahuan (rincian)'!C3 -> SMK TELKOM BANJARBARU
C4: ='Pengetahuan (rincian)'!C4 -> TAHUN PELAJARAN 2025-2026
A6: ='Pengetahuan (rincian)'!A6 -> MATA PELAJARAN : | D6: ='Pengetahuan (rincian)'!D6 -> BASIS DATA | AY6: ='Pengetahuan (rincian)'!AV6 -> SEMESTER : GANJIL
A9: NO | B9: NOMOR INDUK | D9: NAMA SISWA | E9: ='Pengetahuan (rincian)'!E9 -> NILAI PADA MASING-MASING ELEMEN | AV9: NILAI TES
E10: =KD!B22 -> Memahami konsep dasar basis data | H10: =KD!B23 -> Mendeskripsikan Model Data dan Hubungan Antar Entitas | K10: =KD!B24 -> Mengimplementasikan Relasi Data | N10: =KD!B25 | Q10: =KD!B26 | T10: =KD!B27 | W10: =KD!B28 | Z10: =KD!B29 | AC10: =KD!B30 | AF10: =KD!B31 | AI10: =KD!B32 | AL10: =KD!B33 | AO10: =KD!B34 | AR10: =KD!B35 | AU10: NPF | AV10: NPJ (Nilai Project) | AX10: NPT (Nilai Praktek) [WAJIB DIISI]
E11: NS | F11: R | G11: NA | H11: NS | I11: R | J11: NA | K11: NS | L11: R | M11: NA | N11: NS | O11: R | P11: NA | Q11: NS | R11: R | S11: NA | T11: NS | U11: R | V11: NA | W11: NS | X11: R | Y11: NA | Z11: NS | AA11: R | AB11: NA | AC11: NS | AD11: R | AE11: NA | AF11: NS | AG11: R | AH11: NA | AI11: NS | AJ11: R | AK11: NA | AL11: NS | AM11: R | AN11: NA | AO11: NS | AP11: R | AQ11: NA | AR11: NS | AS11: R | AT11: NA | AV11: NS | AW11: R | AX11: NS | AY11: R
A12: =IF('Pengetahuan (rincian)'!A12="","",'Pengetahuan (rincian)'!A12) -> 1 | B12: ='Pengetahuan (rincian)'!B12 -> 543241108 | D12: ='Pengetahuan (rincian)'!D12 -> AHMAD FAIZH GIFFARY SYA'BANA | E12: ='Pengetahuan (rincian)'!E12 -> 90 | F12: ='Pengetahuan (rincian)'!F12 | G12: ='Pengetahuan (rincian)'!G12 -> 90 | H12: ='Pengetahuan (rincian)'!H12 -> 80 | I12: ='Pengetahuan (rincian)'!I12 | J12: ='Pengetahuan (rincian)'!J12 -> 80 | K12: ='Pengetahuan (rincian)'!K12 -> 90 | ... AY12: ='Pengetahuan (rincian)'!AY12
A13: =IF('Pengetahuan (rincian)'!A13="","",'Pengetahuan (rincian)'!A13) -> 2 | B13: ='Pengetahuan (rincian)'!B13 -> 543241071 | D13: ='Pengetahuan (rincian)'!D13 -> AHMAD SAJIDAN ATHAILLAH | E13: ='Pengetahuan (rincian)'!E13 -> 90 | F13: ='Pengetahuan (rincian)'!F13 | G13: ='Pengetahuan (rincian)'!G13 -> 90 | H13: ='Pengetahuan (rincian)'!H13 -> 80 | I13: ='Pengetahuan (rincian)'!I13 | J13: ='Pengetahuan (rincian)'!J13 -> 80 | K13: ='Pengetahuan (rincian)'!K13 -> 90 | ... AY13: ='Pengetahuan (rincian)'!AY13
A14: =IF('Pengetahuan (rincian)'!A14="","",'Pengetahuan (rincian)'!A14) -> 3 | B14: ='Pengetahuan (rincian)'!B14 -> 543241110 | D14: ='Pengetahuan (rincian)'!D14 -> AKHMAD SUPRIYADI | E14: ='Pengetahuan (rincian)'!E14 -> 92 | F14: ='Pengetahuan (rincian)'!F14 | G14: ='Pengetahuan (rincian)'!G14 -> 92 | H14: ='Pengetahuan (rincian)'!H14 -> 95 | I14: ='Pengetahuan (rincian)'!I14 | J14: ='Pengetahuan (rincian)'!J14 -> 95 | K14: ='Pengetahuan (rincian)'!K14 -> 92 | ... AY14: ='Pengetahuan (rincian)'!AY14
A15: =IF('Pengetahuan (rincian)'!A15="","",'Pengetahuan (rincian)'!A15) -> 4 | B15: ='Pengetahuan (rincian)'!B15 -> 543241112 | D15: ='Pengetahuan (rincian)'!D15 -> ALFIAH RAHMAWATI PUTRI | E15: ='Pengetahuan (rincian)'!E15 -> 95 | F15: ='Pengetahuan (rincian)'!F15 | G15: ='Pengetahuan (rincian)'!G15 -> 95 | H15: ='Pengetahuan (rincian)'!H15 -> 93 | I15: ='Pengetahuan (rincian)'!I15 | J15: ='Pengetahuan (rincian)'!J15 -> 93 | K15: ='Pengetahuan (rincian)'!K15 -> 95 | ... AY15: ='Pengetahuan (rincian)'!AY15
A16: =IF('Pengetahuan (rincian)'!A16="","",'Pengetahuan (rincian)'!A16) -> 5 | B16: ='Pengetahuan (rincian)'!B16 -> 543241113 | D16: ='Pengetahuan (rincian)'!D16 -> ARMAN DUARTE | E16: ='Pengetahuan (rincian)'!E16 -> 92 | F16: ='Pengetahuan (rincian)'!F16 | G16: ='Pengetahuan (rincian)'!G16 -> 92 | H16: ='Pengetahuan (rincian)'!H16 -> 95 | I16: ='Pengetahuan (rincian)'!I16 | J16: ='Pengetahuan (rincian)'!J16 -> 95 | K16: ='Pengetahuan (rincian)'!K16 -> 92 | ... AY16: ='Pengetahuan (rincian)'!AY16
A17: =IF('Pengetahuan (rincian)'!A17="","",'Pengetahuan (rincian)'!A17) -> 6 | B17: ='Pengetahuan (rincian)'!B17 -> 543241114 | D17: ='Pengetahuan (rincian)'!D17 -> AULIA AGUSTIANTI RAMADHANI | E17: ='Pengetahuan (rincian)'!E17 -> 95 | F17: ='Pengetahuan (rincian)'!F17 | G17: ='Pengetahuan (rincian)'!G17 -> 95 | H17: ='Pengetahuan (rincian)'!H17 -> 93 | I17: ='Pengetahuan (rincian)'!I17 | J17: ='Pengetahuan (rincian)'!J17 -> 93 | K17: ='Pengetahuan (rincian)'!K17 -> 95 | ... AY17: ='Pengetahuan (rincian)'!AY17
A18: =IF('Pengetahuan (rincian)'!A18="","",'Pengetahuan (rincian)'!A18) -> 7 | B18: ='Pengetahuan (rincian)'!B18 -> 543241025 | D18: ='Pengetahuan (rincian)'!D18 -> BETARUS MARCHIANO BOANERGES | E18: ='Pengetahuan (rincian)'!E18 -> 90 | F18: ='Pengetahuan (rincian)'!F18 | G18: ='Pengetahuan (rincian)'!G18 -> 90 | H18: ='Pengetahuan (rincian)'!H18 -> 95 | I18: ='Pengetahuan (rincian)'!I18 | J18: ='Pengetahuan (rincian)'!J18 -> 95 | K18: ='Pengetahuan (rincian)'!K18 -> 90 | ... AY18: ='Pengetahuan (rincian)'!AY18
A19: =IF('Pengetahuan (rincian)'!A19="","",'Pengetahuan (rincian)'!A19) -> 8 | B19: ='Pengetahuan (rincian)'!B19 -> 543241078 | D19: ='Pengetahuan (rincian)'!D19 -> DANIEL DIMAS NUGROHO | E19: ='Pengetahuan (rincian)'!E19 -> 88 | F19: ='Pengetahuan (rincian)'!F19 | G19: ='Pengetahuan (rincian)'!G19 -> 88 | H19: ='Pengetahuan (rincian)'!H19 -> 95 | I19: ='Pengetahuan (rincian)'!I19 | J19: ='Pengetahuan (rincian)'!J19 -> 95 | K19: ='Pengetahuan (rincian)'!K19 -> 88 | ... AY19: ='Pengetahuan (rincian)'!AY19
A20: =IF('Pengetahuan (rincian)'!A20="","",'Pengetahuan (rincian)'!A20) -> 9 | B20: ='Pengetahuan (rincian)'!B20 -> 543241080 | D20: ='Pengetahuan (rincian)'!D20 -> DEDE FEBRYLIANTONI | E20: ='Pengetahuan (rincian)'!E20 -> 88 | F20: ='Pengetahuan (rincian)'!F20 | G20: ='Pengetahuan (rincian)'!G20 -> 88 | H20: ='Pengetahuan (rincian)'!H20 -> 95 | I20: ='Pengetahuan (rincian)'!I20 | J20: ='Pengetahuan (rincian)'!J20 -> 95 | K20: ='Pengetahuan (rincian)'!K20 -> 88 | ... AY20: ='Pengetahuan (rincian)'!AY20
A21: =IF('Pengetahuan (rincian)'!A21="","",'Pengetahuan (rincian)'!A21) -> 10 | B21: ='Pengetahuan (rincian)'!B21 -> 543241081 | D21: ='Pengetahuan (rincian)'!D21 -> GHANIY PUTRI AR RAZZAQ | E21: ='Pengetahuan (rincian)'!E21 -> 95 | F21: ='Pengetahuan (rincian)'!F21 | G21: ='Pengetahuan (rincian)'!G21 -> 95 | H21: ='Pengetahuan (rincian)'!H21 -> 90 | I21: ='Pengetahuan (rincian)'!I21 | J21: ='Pengetahuan (rincian)'!J21 -> 90 | K21: ='Pengetahuan (rincian)'!K21 -> 95 | ... AY21: ='Pengetahuan (rincian)'!AY21
A22: =IF('Pengetahuan (rincian)'!A22="","",'Pengetahuan (rincian)'!A22) -> 11 | B22: ='Pengetahuan (rincian)'!B22 -> 543241119 | D22: ='Pengetahuan (rincian)'!D22 -> HAIKA MEZZIA AVEIRA | E22: ='Pengetahuan (rincian)'!E22 -> 95 | F22: ='Pengetahuan (rincian)'!F22 | G22: ='Pengetahuan (rincian)'!G22 -> 95 | H22: ='Pengetahuan (rincian)'!H22 -> 95 | I22: ='Pengetahuan (rincian)'!I22 | J22: ='Pengetahuan (rincian)'!J22 -> 95 | K22: ='Pengetahuan (rincian)'!K22 -> 95 | ... AY22: ='Pengetahuan (rincian)'!AY22
A23: =IF('Pengetahuan (rincian)'!A23="","",'Pengetahuan (rincian)'!A23) -> 12 | B23: ='Pengetahuan (rincian)'!B23 -> 543241009 | D23: ='Pengetahuan (rincian)'!D23 -> KEVIN APTA | E23: ='Pengetahuan (rincian)'!E23 -> 95 | F23: ='Pengetahuan (rincian)'!F23 | G23: ='Pengetahuan (rincian)'!G23 -> 95 | H23: ='Pengetahuan (rincian)'!H23 -> 90 | I23: ='Pengetahuan (rincian)'!I23 | J23: ='Pengetahuan (rincian)'!J23 -> 90 | K23: ='Pengetahuan (rincian)'!K23 -> 95 | ... AY23: ='Pengetahuan (rincian)'!AY23
... A51: =IF('Pengetahuan (rincian)'!A51="","",'Pengetahuan (rincian)'!A51) -> 40 | B51: ='Pengetahuan (rincian)'!B51 | D51: ='Pengetahuan (rincian)'!D51 | E51: ='Pengetahuan (rincian)'!E51 | F51: ='Pengetahuan (rincian)'!F51 | G51: ='Pengetahuan (rincian)'!G51 | H51: ='Pengetahuan (rincian)'!H51 | I51: ='Pengetahuan (rincian)'!I51 | J51: ='Pengetahuan (rincian)'!J51 | K51: ='Pengetahuan (rincian)'!K51 | ... AY51: ='Pengetahuan (rincian)'!AY51
B52: ='Pengetahuan (rincian)'!B52 | D52: ='Pengetahuan (rincian)'!D52 | V52: =IF(T52="","",MAX(T52:U52)) | Y52: =IF(W52="","",MAX(W52:X52)) | AB52: =IF(Z52="","",MAX(Z52:AA52)) | AE52: =IF(AC52="","",MAX(AC52:AD52)) | AH52: =IF(AF52="","",MAX(AF52:AG52)) | AK52: =IF(AI52="","",MAX(AI52:AJ52)) | AN52: =IF(AL52="","",MAX(AL52:AM52)) | AQ52: =IF(AO52="","",MAX(AO52:AP52)) | AT52: =IF(AR52="","",MAX(AR52:AS52)) | AU52: =IF(E52="","",ROUND(AVERAGE(G52,J52,M52,P52,S52,V52,AH52,AQ52,AT52,Y52,AB52,AE52,AK52,AN52),0))
B53: =IF('Pengetahuan (rincian)'!B52="","",'Pengetahuan (rincian)'!B52)
A54: Keterangan :
A55: 1 | B55: Isian ini digunakan untuk membantu mengisi penilaian pengetahuan | N55: ='Pengetahuan (rincian)'!N54 -> Banjarbaru, Agustus 2025
A56: 2 | B56: Isikan hasil penilaian harian sesuai dengan kompetensi dasar (0 - 100) | N56: Guru Mata Pelajaran
A57: 3 | B57: NS : Nilai Semula | D57: NPF : Nilai Portofolio
B58: R : Nilai Remedial | D58: NPJ : Nilai Proyek
B59: NA : Nilai Akhir KD | D59: NPT : Nilai Praktik
N60: ='Pengetahuan (rincian)'!N59
A61: Copyright Ó SMKTelkom SP Banjarbaru – Juli 2014 Ver 1.0

Sheet Data Nilai Bermasalah
A1: ='Pengetahuan (rincian)'!A1 -> XIE RPL | G1: Confidential
C2: ="DATA RINCI NILAI BERMASALAH KELAS "&A1 -> DATA RINCI NILAI BERMASALAH KELAS XIE RPL
C3: ='Pengetahuan (rincian)'!C3 -> SMK TELKOM BANJARBARU
C4: ='Pengetahuan (rincian)'!C4 -> TAHUN PELAJARAN 2025-2026
A6: ='Pengetahuan (rincian)'!A6 -> MATA PELAJARAN : | D6: ='Pengetahuan (rincian)'!D6 -> BASIS DATA | G6: ='Pengetahuan (rincian)'!AV6 -> SEMESTER : GANJIL
A9: NO | B9: NOMOR INDUK | D9: NAMA SISWA | E9: TUGAS (Google Classrom, LMS, dan lain-lain) | F9: UJIAN/ULANGAN HARIAN | G9: LAIN-LAIN (Sikap, Kehadiran atau lainnya yang di anggap perlu)
A11: =IF('Pengetahuan (rincian)'!A12="","",'Pengetahuan (rincian)'!A12) -> 1 | B11: ='Pengetahuan (rincian)'!B12 -> 543241108 | D11: ='Pengetahuan (rincian)'!D12 -> AHMAD FAIZH GIFFARY SYA'BANA
A12: =IF('Pengetahuan (rincian)'!A13="","",'Pengetahuan (rincian)'!A13) -> 2 | B12: ='Pengetahuan (rincian)'!B13 -> 543241071 | D12: ='Pengetahuan (rincian)'!D13 -> AHMAD SAJIDAN ATHAILLAH
A13: =IF('Pengetahuan (rincian)'!A14="","",'Pengetahuan (rincian)'!A14) -> 3 | B13: ='Pengetahuan (rincian)'!B14 -> 543241110 | D13: ='Pengetahuan (rincian)'!D14 -> AKHMAD SUPRIYADI
A14: =IF('Pengetahuan (rincian)'!A15="","",'Pengetahuan (rincian)'!A15) -> 4 | B14: ='Pengetahuan (rincian)'!B15 -> 543241112 | D14: ='Pengetahuan (rincian)'!D15 -> ALFIAH RAHMAWATI PUTRI
A15: =IF('Pengetahuan (rincian)'!A16="","",'Pengetahuan (rincian)'!A16) -> 5 | B15: ='Pengetahuan (rincian)'!B16 -> 543241113 | D15: ='Pengetahuan (rincian)'!D16 -> ARMAN DUARTE
A16: =IF('Pengetahuan (rincian)'!A17="","",'Pengetahuan (rincian)'!A17) -> 6 | B16: ='Pengetahuan (rincian)'!B17 -> 543241114 | D16: ='Pengetahuan (rincian)'!D17 -> AULIA AGUSTIANTI RAMADHANI
A17: =IF('Pengetahuan (rincian)'!A18="","",'Pengetahuan (rincian)'!A18) -> 7 | B17: ='Pengetahuan (rincian)'!B18 -> 543241025 | D17: ='Pengetahuan (rincian)'!D18 -> BETARUS MARCHIANO BOANERGES
A18: =IF('Pengetahuan (rincian)'!A19="","",'Pengetahuan (rincian)'!A19) -> 8 | B18: ='Pengetahuan (rincian)'!B19 -> 543241078 | D18: ='Pengetahuan (rincian)'!D19 -> DANIEL DIMAS NUGROHO
